<?xml version="1.0" encoding="UTF-8"?>
<testng-results skipped="3" failed="2" total="6" passed="1">
  <reporter-output>
  </reporter-output>
  <suite name="Default suite" duration-ms="204" started-at="2019-12-08T13:26:21Z" finished-at="2019-12-08T13:26:21Z">
    <groups>
    </groups>
    <test name="Default test" duration-ms="204" started-at="2019-12-08T13:26:21Z" finished-at="2019-12-08T13:26:21Z">
      <class name="Rerun.RetryFailesTestCases">
        <test-method status="PASS" signature="test1()[pri:0, instance:Rerun.RetryFailesTestCases@42e26948]" name="test1" duration-ms="38" started-at="2019-12-08T18:56:21Z" finished-at="2019-12-08T18:56:21Z">
          <reporter-output>
          </reporter-output>
        </test-method> <!-- test1 -->
        <test-method status="SKIP" signature="test2()[pri:0, instance:Rerun.RetryFailesTestCases@42e26948]" name="test2" duration-ms="6" started-at="2019-12-08T18:56:21Z" finished-at="2019-12-08T18:56:21Z">
          <exception class="java.lang.ArithmeticException">
            <message>
              <![CDATA[/ by zero]]>
            </message>
            <full-stacktrace>
              <![CDATA[java.lang.ArithmeticException: / by zero
	at Rerun.RetryFailesTestCases.test2(RetryFailesTestCases.java:16)
	at sun.reflect.NativeMethodAccessorImpl.invoke0(Native Method)
	at sun.reflect.NativeMethodAccessorImpl.invoke(NativeMethodAccessorImpl.java:62)
	at sun.reflect.DelegatingMethodAccessorImpl.invoke(DelegatingMethodAccessorImpl.java:43)
	at java.lang.reflect.Method.invoke(Method.java:498)
	at org.testng.internal.MethodInvocationHelper.invokeMethod(MethodInvocationHelper.java:86)
	at org.testng.internal.Invoker.invokeMethod(Invoker.java:646)
	at org.testng.internal.Invoker.invokeTestMethod(Invoker.java:823)
	at org.testng.internal.Invoker.invokeTestMethods(Invoker.java:1131)
	at org.testng.internal.TestMethodWorker.invokeTestMethods(TestMethodWorker.java:129)
	at org.testng.internal.TestMethodWorker.run(TestMethodWorker.java:112)
	at org.testng.TestRunner.privateRun(TestRunner.java:778)
	at org.testng.TestRunner.run(TestRunner.java:632)
	at org.testng.SuiteRunner.runTest(SuiteRunner.java:366)
	at org.testng.SuiteRunner.runSequentially(SuiteRunner.java:361)
	at org.testng.SuiteRunner.privateRun(SuiteRunner.java:319)
	at org.testng.SuiteRunner.run(SuiteRunner.java:268)
	at org.testng.SuiteRunnerWorker.runSuite(SuiteRunnerWorker.java:52)
	at org.testng.SuiteRunnerWorker.run(SuiteRunnerWorker.java:86)
	at org.testng.TestNG.runSuitesSequentially(TestNG.java:1225)
	at org.testng.TestNG.runSuitesLocally(TestNG.java:1150)
	at org.testng.TestNG.runSuites(TestNG.java:1075)
	at org.testng.TestNG.run(TestNG.java:1047)
	at org.testng.remote.AbstractRemoteTestNG.run(AbstractRemoteTestNG.java:126)
	at org.testng.remote.RemoteTestNG.initAndRun(RemoteTestNG.java:137)
	at org.testng.remote.RemoteTestNG.main(RemoteTestNG.java:58)
]]>
            </full-stacktrace>
          </exception> <!-- java.lang.ArithmeticException -->
          <reporter-output>
          </reporter-output>
        </test-method> <!-- test2 -->
        <test-method status="SKIP" signature="test2()[pri:0, instance:Rerun.RetryFailesTestCases@42e26948]" name="test2" duration-ms="4" started-at="2019-12-08T18:56:21Z" finished-at="2019-12-08T18:56:21Z">
          <exception class="java.lang.ArithmeticException">
            <message>
              <![CDATA[/ by zero]]>
            </message>
            <full-stacktrace>
              <![CDATA[java.lang.ArithmeticException: / by zero
	at Rerun.RetryFailesTestCases.test2(RetryFailesTestCases.java:16)
	at sun.reflect.NativeMethodAccessorImpl.invoke0(Native Method)
	at sun.reflect.NativeMethodAccessorImpl.invoke(NativeMethodAccessorImpl.java:62)
	at sun.reflect.DelegatingMethodAccessorImpl.invoke(DelegatingMethodAccessorImpl.java:43)
	at java.lang.reflect.Method.invoke(Method.java:498)
	at org.testng.internal.MethodInvocationHelper.invokeMethod(MethodInvocationHelper.java:86)
	at org.testng.internal.Invoker.invokeMethod(Invoker.java:646)
	at org.testng.internal.Invoker.retryFailed(Invoker.java:970)
	at org.testng.internal.Invoker.invokeTestMethods(Invoker.java:1149)
	at org.testng.internal.TestMethodWorker.invokeTestMethods(TestMethodWorker.java:129)
	at org.testng.internal.TestMethodWorker.run(TestMethodWorker.java:112)
	at org.testng.TestRunner.privateRun(TestRunner.java:778)
	at org.testng.TestRunner.run(TestRunner.java:632)
	at org.testng.SuiteRunner.runTest(SuiteRunner.java:366)
	at org.testng.SuiteRunner.runSequentially(SuiteRunner.java:361)
	at org.testng.SuiteRunner.privateRun(SuiteRunner.java:319)
	at org.testng.SuiteRunner.run(SuiteRunner.java:268)
	at org.testng.SuiteRunnerWorker.runSuite(SuiteRunnerWorker.java:52)
	at org.testng.SuiteRunnerWorker.run(SuiteRunnerWorker.java:86)
	at org.testng.TestNG.runSuitesSequentially(TestNG.java:1225)
	at org.testng.TestNG.runSuitesLocally(TestNG.java:1150)
	at org.testng.TestNG.runSuites(TestNG.java:1075)
	at org.testng.TestNG.run(TestNG.java:1047)
	at org.testng.remote.AbstractRemoteTestNG.run(AbstractRemoteTestNG.java:126)
	at org.testng.remote.RemoteTestNG.initAndRun(RemoteTestNG.java:137)
	at org.testng.remote.RemoteTestNG.main(RemoteTestNG.java:58)
]]>
            </full-stacktrace>
          </exception> <!-- java.lang.ArithmeticException -->
          <reporter-output>
          </reporter-output>
        </test-method> <!-- test2 -->
        <test-method status="SKIP" signature="test2()[pri:0, instance:Rerun.RetryFailesTestCases@42e26948]" name="test2" duration-ms="8" started-at="2019-12-08T18:56:21Z" finished-at="2019-12-08T18:56:21Z">
          <exception class="java.lang.ArithmeticException">
            <message>
              <![CDATA[/ by zero]]>
            </message>
            <full-stacktrace>
              <![CDATA[java.lang.ArithmeticException: / by zero
	at Rerun.RetryFailesTestCases.test2(RetryFailesTestCases.java:16)
	at sun.reflect.NativeMethodAccessorImpl.invoke0(Native Method)
	at sun.reflect.NativeMethodAccessorImpl.invoke(NativeMethodAccessorImpl.java:62)
	at sun.reflect.DelegatingMethodAccessorImpl.invoke(DelegatingMethodAccessorImpl.java:43)
	at java.lang.reflect.Method.invoke(Method.java:498)
	at org.testng.internal.MethodInvocationHelper.invokeMethod(MethodInvocationHelper.java:86)
	at org.testng.internal.Invoker.invokeMethod(Invoker.java:646)
	at org.testng.internal.Invoker.retryFailed(Invoker.java:970)
	at org.testng.internal.Invoker.invokeTestMethods(Invoker.java:1149)
	at org.testng.internal.TestMethodWorker.invokeTestMethods(TestMethodWorker.java:129)
	at org.testng.internal.TestMethodWorker.run(TestMethodWorker.java:112)
	at org.testng.TestRunner.privateRun(TestRunner.java:778)
	at org.testng.TestRunner.run(TestRunner.java:632)
	at org.testng.SuiteRunner.runTest(SuiteRunner.java:366)
	at org.testng.SuiteRunner.runSequentially(SuiteRunner.java:361)
	at org.testng.SuiteRunner.privateRun(SuiteRunner.java:319)
	at org.testng.SuiteRunner.run(SuiteRunner.java:268)
	at org.testng.SuiteRunnerWorker.runSuite(SuiteRunnerWorker.java:52)
	at org.testng.SuiteRunnerWorker.run(SuiteRunnerWorker.java:86)
	at org.testng.TestNG.runSuitesSequentially(TestNG.java:1225)
	at org.testng.TestNG.runSuitesLocally(TestNG.java:1150)
	at org.testng.TestNG.runSuites(TestNG.java:1075)
	at org.testng.TestNG.run(TestNG.java:1047)
	at org.testng.remote.AbstractRemoteTestNG.run(AbstractRemoteTestNG.java:126)
	at org.testng.remote.RemoteTestNG.initAndRun(RemoteTestNG.java:137)
	at org.testng.remote.RemoteTestNG.main(RemoteTestNG.java:58)
]]>
            </full-stacktrace>
          </exception> <!-- java.lang.ArithmeticException -->
          <reporter-output>
          </reporter-output>
        </test-method> <!-- test2 -->
        <test-method status="FAIL" signature="test2()[pri:0, instance:Rerun.RetryFailesTestCases@42e26948]" name="test2" duration-ms="2" started-at="2019-12-08T18:56:21Z" finished-at="2019-12-08T18:56:21Z">
          <exception class="java.lang.ArithmeticException">
            <message>
              <![CDATA[/ by zero]]>
            </message>
            <full-stacktrace>
              <![CDATA[java.lang.ArithmeticException: / by zero
	at Rerun.RetryFailesTestCases.test2(RetryFailesTestCases.java:16)
	at sun.reflect.NativeMethodAccessorImpl.invoke0(Native Method)
	at sun.reflect.NativeMethodAccessorImpl.invoke(NativeMethodAccessorImpl.java:62)
	at sun.reflect.DelegatingMethodAccessorImpl.invoke(DelegatingMethodAccessorImpl.java:43)
	at java.lang.reflect.Method.invoke(Method.java:498)
	at org.testng.internal.MethodInvocationHelper.invokeMethod(MethodInvocationHelper.java:86)
	at org.testng.internal.Invoker.invokeMethod(Invoker.java:646)
	at org.testng.internal.Invoker.retryFailed(Invoker.java:970)
	at org.testng.internal.Invoker.invokeTestMethods(Invoker.java:1149)
	at org.testng.internal.TestMethodWorker.invokeTestMethods(TestMethodWorker.java:129)
	at org.testng.internal.TestMethodWorker.run(TestMethodWorker.java:112)
	at org.testng.TestRunner.privateRun(TestRunner.java:778)
	at org.testng.TestRunner.run(TestRunner.java:632)
	at org.testng.SuiteRunner.runTest(SuiteRunner.java:366)
	at org.testng.SuiteRunner.runSequentially(SuiteRunner.java:361)
	at org.testng.SuiteRunner.privateRun(SuiteRunner.java:319)
	at org.testng.SuiteRunner.run(SuiteRunner.java:268)
	at org.testng.SuiteRunnerWorker.runSuite(SuiteRunnerWorker.java:52)
	at org.testng.SuiteRunnerWorker.run(SuiteRunnerWorker.java:86)
	at org.testng.TestNG.runSuitesSequentially(TestNG.java:1225)
	at org.testng.TestNG.runSuitesLocally(TestNG.java:1150)
	at org.testng.TestNG.runSuites(TestNG.java:1075)
	at org.testng.TestNG.run(TestNG.java:1047)
	at org.testng.remote.AbstractRemoteTestNG.run(AbstractRemoteTestNG.java:126)
	at org.testng.remote.RemoteTestNG.initAndRun(RemoteTestNG.java:137)
	at org.testng.remote.RemoteTestNG.main(RemoteTestNG.java:58)
]]>
            </full-stacktrace>
          </exception> <!-- java.lang.ArithmeticException -->
          <reporter-output>
          </reporter-output>
        </test-method> <!-- test2 -->
        <test-method status="FAIL" signature="test3()[pri:0, instance:Rerun.RetryFailesTestCases@42e26948]" name="test3" duration-ms="10" started-at="2019-12-08T18:56:21Z" finished-at="2019-12-08T18:56:21Z">
          <exception class="java.lang.AssertionError">
            <message>
              <![CDATA[null]]>
            </message>
            <full-stacktrace>
              <![CDATA[java.lang.AssertionError: null
	at org.testng.Assert.fail(Assert.java:94)
	at org.testng.Assert.fail(Assert.java:101)
	at Rerun.RetryFailesTestCases.test3(RetryFailesTestCases.java:22)
	at sun.reflect.NativeMethodAccessorImpl.invoke0(Native Method)
	at sun.reflect.NativeMethodAccessorImpl.invoke(NativeMethodAccessorImpl.java:62)
	at sun.reflect.DelegatingMethodAccessorImpl.invoke(DelegatingMethodAccessorImpl.java:43)
	at java.lang.reflect.Method.invoke(Method.java:498)
	at org.testng.internal.MethodInvocationHelper.invokeMethod(MethodInvocationHelper.java:86)
	at org.testng.internal.Invoker.invokeMethod(Invoker.java:646)
	at org.testng.internal.Invoker.invokeTestMethod(Invoker.java:823)
	at org.testng.internal.Invoker.invokeTestMethods(Invoker.java:1131)
	at org.testng.internal.TestMethodWorker.invokeTestMethods(TestMethodWorker.java:129)
	at org.testng.internal.TestMethodWorker.run(TestMethodWorker.java:112)
	at org.testng.TestRunner.privateRun(TestRunner.java:778)
	at org.testng.TestRunner.run(TestRunner.java:632)
	at org.testng.SuiteRunner.runTest(SuiteRunner.java:366)
	at org.testng.SuiteRunner.runSequentially(SuiteRunner.java:361)
	at org.testng.SuiteRunner.privateRun(SuiteRunner.java:319)
	at org.testng.SuiteRunner.run(SuiteRunner.java:268)
	at org.testng.SuiteRunnerWorker.runSuite(SuiteRunnerWorker.java:52)
	at org.testng.SuiteRunnerWorker.run(SuiteRunnerWorker.java:86)
	at org.testng.TestNG.runSuitesSequentially(TestNG.java:1225)
	at org.testng.TestNG.runSuitesLocally(TestNG.java:1150)
	at org.testng.TestNG.runSuites(TestNG.java:1075)
	at org.testng.TestNG.run(TestNG.java:1047)
	at org.testng.remote.AbstractRemoteTestNG.run(AbstractRemoteTestNG.java:126)
	at org.testng.remote.RemoteTestNG.initAndRun(RemoteTestNG.java:137)
	at org.testng.remote.RemoteTestNG.main(RemoteTestNG.java:58)
]]>
            </full-stacktrace>
          </exception> <!-- java.lang.AssertionError -->
          <reporter-output>
          </reporter-output>
        </test-method> <!-- test3 -->
      </class> <!-- Rerun.RetryFailesTestCases -->
    </test> <!-- Default test -->
  </suite> <!-- Default suite -->
</testng-results>
